<?xml version="1.0" encoding="UTF-8"?>
<testng-results total="1" passed="0" failed="0" skipped="1">
  <reporter-output>
  </reporter-output>
  <suite started-at="2018-11-23T10:24:55Z" name="Default suite" finished-at="2018-11-23T10:25:03Z" duration-ms="8072">
    <groups>
    </groups>
    <test started-at="2018-11-23T10:24:55Z" name="Default test" finished-at="2018-11-23T10:25:03Z" duration-ms="8072">
      <class name="pack.Datadrivenfr">
        <test-method signature="regst(java.lang.String, java.lang.String, java.lang.String, java.lang.String, java.lang.String, java.lang.String)[pri:0, instance:pack.Datadrivenfr@445b295b]" started-at="2018-11-23T12:25:03Z" name="regst" data-provider="data" finished-at="2018-11-23T12:25:03Z" duration-ms="0" status="SKIP">
          <exception class="java.lang.RuntimeException">
            <message>
              <![CDATA[java.lang.ArrayIndexOutOfBoundsException: 0]]>
            </message>
            <full-stacktrace>
              <![CDATA[java.lang.RuntimeException: java.lang.ArrayIndexOutOfBoundsException: 0
	at org.testng.internal.MethodInvocationHelper.invokeDataProvider(MethodInvocationHelper.java:162)
	at org.testng.internal.Parameters.handleParameters(Parameters.java:430)
	at org.testng.internal.Invoker.handleParameters(Invoker.java:1270)
	at org.testng.internal.Invoker.createParameters(Invoker.java:985)
	at org.testng.internal.Invoker.invokeTestMethods(Invoker.java:1075)
	at org.testng.internal.TestMethodWorker.invokeTestMethods(TestMethodWorker.java:125)
	at org.testng.internal.TestMethodWorker.run(TestMethodWorker.java:108)
	at org.testng.TestRunner.privateRun(TestRunner.java:774)
	at org.testng.TestRunner.run(TestRunner.java:624)
	at org.testng.SuiteRunner.runTest(SuiteRunner.java:359)
	at org.testng.SuiteRunner.runSequentially(SuiteRunner.java:354)
	at org.testng.SuiteRunner.privateRun(SuiteRunner.java:312)
	at org.testng.SuiteRunner.run(SuiteRunner.java:261)
	at org.testng.SuiteRunnerWorker.runSuite(SuiteRunnerWorker.java:52)
	at org.testng.SuiteRunnerWorker.run(SuiteRunnerWorker.java:86)
	at org.testng.TestNG.runSuitesSequentially(TestNG.java:1215)
	at org.testng.TestNG.runSuitesLocally(TestNG.java:1140)
	at org.testng.TestNG.run(TestNG.java:1048)
	at org.testng.remote.AbstractRemoteTestNG.run(AbstractRemoteTestNG.java:114)
	at org.testng.remote.RemoteTestNG.initAndRun(RemoteTestNG.java:251)
	at org.testng.remote.RemoteTestNG.main(RemoteTestNG.java:77)
Caused by: java.lang.ArrayIndexOutOfBoundsException: 0
	at pack.Datadrivenfr.getdata(Datadrivenfr.java:54)
	at java.base/jdk.internal.reflect.NativeMethodAccessorImpl.invoke0(Native Method)
	at java.base/jdk.internal.reflect.NativeMethodAccessorImpl.invoke(Unknown Source)
	at java.base/jdk.internal.reflect.DelegatingMethodAccessorImpl.invoke(Unknown Source)
	at java.base/java.lang.reflect.Method.invoke(Unknown Source)
	at org.testng.internal.MethodInvocationHelper.invokeMethod(MethodInvocationHelper.java:85)
	at org.testng.internal.MethodInvocationHelper.invokeDataProvider(MethodInvocationHelper.java:136)
	... 20 more
]]>
            </full-stacktrace>
          </exception> <!-- java.lang.RuntimeException -->
          <reporter-output>
          </reporter-output>
        </test-method> <!-- regst -->
      </class> <!-- pack.Datadrivenfr -->
    </test> <!-- Default test -->
  </suite> <!-- Default suite -->
</testng-results>
